Workbook
Name UPDATE: 'Data Sheet'!$E$1

Sheet Profit & Loss
A1: ='Data Sheet'!B1 -> ITC LTD | H1: =UPDATE | M1: SCREENER.IN
A3: Narration | B3: ='Data Sheet'!B16 -> 40999 | C3: ='Data Sheet'!C16 -> 41364 | D3: ='Data Sheet'!D16 -> 41729 | E3: ='Data Sheet'!E16 -> 42094 | F3: ='Data Sheet'!F16 -> 42460 | G3: ='Data Sheet'!G16 -> 42825 | H3: ='Data Sheet'!H16 -> 43190 | I3: ='Data Sheet'!I16 -> 43555 | ... K3: ='Data Sheet'!K16 -> 44286 | L3: Trailing | M3: Best Case | N3: Worst Case
A4: Sales | B4: ='Data Sheet'!B17 -> 26516.03 | C4: ='Data Sheet'!C17 -> 31618.33 | D4: ='Data Sheet'!D17 -> 35306.43 | E4: ='Data Sheet'!E17 -> 38817.15 | F4: ='Data Sheet'!F17 -> 39192.1 | G4: ='Data Sheet'!G17 -> 42767.6 | H4: ='Data Sheet'!H17 -> 43448.94 | I4: ='Data Sheet'!I17 -> 48339.58 | ... K4: ='Data Sheet'!K17 -> 49257.45 | L4: =SUM(Quarters!H4:K4) -> 52745.96 | M4: =$K4+M23*K4 -> 52745.96 | N4: =$K4+N23*L4 -> 51510.32
A5: Expenses | B5: =SUM('Data Sheet'!B18,'Data Sheet'!B20:B24, -1*'Data Sheet'!B19) -> 17272.07 | C5: =SUM('Data Sheet'!C18,'Data Sheet'!C20:C24, -1*'Data Sheet'!C19) -> 20397.75 | D5: =SUM('Data Sheet'!D18,'Data Sheet'!D20:D24, -1*'Data Sheet'!D19) -> 22226.53 | E5: =SUM('Data Sheet'!E18,'Data Sheet'!E20:E24, -1*'Data Sheet'!E19) -> 24565.53 | F5: =SUM('Data Sheet'!F18,'Data Sheet'!F20:F24, -1*'Data Sheet'!F19) -> 24660.61 | G5: =SUM('Data Sheet'!G18,'Data Sheet'!G20:G24, -1*'Data Sheet'!G19) -> 27298.09 | H5: =SUM('Data Sheet'!H18,'Data Sheet'!H20:H24, -1*'Data Sheet'!H19) -> 26928.35 | I5: =SUM('Data Sheet'!I18,'Data Sheet'!I20:I24, -1*'Data Sheet'!I19) -> 29802.19 | ... K5: =SUM('Data Sheet'!K18,'Data Sheet'!K20:K24, -1*'Data Sheet'!K19) -> 32192.67 | L5: =SUM(Quarters!H5:K5) -> 34245.08 | M5: =M4-M6 -> 33028.509 | N5: =N4-N6 -> 33442.846
A6: Operating Profit | B6: =B4-B5 -> 9243.96 | C6: =C4-C5 -> 11220.58 | D6: =D4-D5 -> 13079.9 | E6: =E4-E5 -> 14251.62 | F6: =F4-F5 -> 14531.49 | G6: =G4-G5 -> 15469.51 | H6: =H4-H5 -> 16520.59 | I6: =I4-I5 -> 18537.39 | ... K6: =K4-K5 -> 17064.78 | L6: =SUM(Quarters!H6:K6) -> 18500.88 | M6: =M4*M24 -> 19717.451 | N6: =N4*N24 -> 18067.474
A7: Other Income | B7: ='Data Sheet'!B25 -> 771.71 | C7: ='Data Sheet'!C25 -> 852.31 | D7: ='Data Sheet'!D25 -> 965.74 | E7: ='Data Sheet'!E25 -> 1229.35 | F7: ='Data Sheet'!F25 -> 1483.11 | G7: ='Data Sheet'!G25 -> 1758.63 | H7: ='Data Sheet'!H25 -> 2239.81 | I7: ='Data Sheet'!I25 -> 2080.44 | ... K7: ='Data Sheet'!K25 -> 2576.95 | L7: =SUM(Quarters!H7:K7) -> 2154.47 | M7: 0 | N7: 0
A8: Depreciation | B8: ='Data Sheet'!B26 -> 745.48 | C8: ='Data Sheet'!C26 -> 859.11 | D8: ='Data Sheet'!D26 -> 964.92 | E8: ='Data Sheet'!E26 -> 1027.96 | F8: ='Data Sheet'!F26 -> 1077.4 | G8: ='Data Sheet'!G26 -> 1152.79 | H8: ='Data Sheet'!H26 -> 1236.28 | I8: ='Data Sheet'!I26 -> 1396.61 | ... K8: ='Data Sheet'!K26 -> 1645.59 | L8: =SUM(Quarters!H8:K8) -> 1640.73 | M8: =+$L8 -> 1640.73 | N8: =+$L8 -> 1640.73
A9: Interest | B9: ='Data Sheet'!B27 -> 102.04 | C9: ='Data Sheet'!C27 -> 108.13 | D9: ='Data Sheet'!D27 -> 29.17 | E9: ='Data Sheet'!E27 -> 90.96 | F9: ='Data Sheet'!F27 -> 78.13 | G9: ='Data Sheet'!G27 -> 49.03 | H9: ='Data Sheet'!H27 -> 115.01 | I9: ='Data Sheet'!I27 -> 71.4 | ... K9: ='Data Sheet'!K27 -> 57.97 | L9: =SUM(Quarters!H9:K9) -> 38.1 | M9: =+$L9 -> 38.1 | N9: =+$L9 -> 38.1
A10: Profit before tax | B10: ='Data Sheet'!B28 -> 9168.15 | C10: ='Data Sheet'!C28 -> 11105.65 | D10: ='Data Sheet'!D28 -> 13051.55 | E10: ='Data Sheet'!E28 -> 14362.05 | F10: ='Data Sheet'!F28 -> 14859.07 | G10: ='Data Sheet'!G28 -> 16026.32 | H10: ='Data Sheet'!H28 -> 17409.11 | I10: ='Data Sheet'!I28 -> 19149.82 | ... K10: ='Data Sheet'!K28 -> 17938.17 | L10: =SUM(Quarters!H10:K10) -> 18976.52 | M10: =M6+M7-SUM(M8:M9) -> 18038.621 | N10: =N6+N7-SUM(N8:N9) -> 16388.644
A11: Tax | B11: ='Data Sheet'!B29 -> 2845.76 | C11: ='Data Sheet'!C29 -> 3412.07 | D11: ='Data Sheet'!D29 -> 4060.93 | E11: ='Data Sheet'!E29 -> 4596.42 | F11: ='Data Sheet'!F29 -> 5358.21 | G11: ='Data Sheet'!G29 -> 5549.09 | H11: ='Data Sheet'!H29 -> 5916.43 | I11: ='Data Sheet'!I29 -> 6313.92 | ... K11: ='Data Sheet'!K29 -> 4555.29 | L11: =SUM(Quarters!H11:K11) -> 4810.35 | M11: =IF($L10>0,$L11/$L10,0) -> 0.25348958 | N11: =IF($L10>0,$L11/$L10,0) -> 0.25348958
A12: Net profit | B12: ='Data Sheet'!B30 -> 6258.14 | C12: ='Data Sheet'!C30 -> 7608.07 | D12: ='Data Sheet'!D30 -> 8891.38 | E12: ='Data Sheet'!E30 -> 9663.17 | F12: ='Data Sheet'!F30 -> 9344.45 | G12: ='Data Sheet'!G30 -> 10289.44 | H12: ='Data Sheet'!H30 -> 11271.2 | I12: ='Data Sheet'!I30 -> 12592.33 | ... K12: ='Data Sheet'!K30 -> 13161.19 | L12: =SUM(Quarters!H12:K12) -> 13926.67 | M12: =M10-M11*M10 -> 13466.019 | N12: =N10-N11*N10 -> 12234.293
A13: EPS | B13: =IF('Data Sheet'!B93>0,B12/'Data Sheet'!B93,0) -> 5.3362495 | C13: =IF('Data Sheet'!C93>0,C12/'Data Sheet'!C93,0) -> 6.4188497 | D13: =IF('Data Sheet'!D93>0,D12/'Data Sheet'!D93,0) -> 7.4530839 | E13: =IF('Data Sheet'!E93>0,E12/'Data Sheet'!E93,0) -> 8.0370364 | F13: =IF('Data Sheet'!F93>0,F12/'Data Sheet'!F93,0) -> 7.7413676 | G13: =IF('Data Sheet'!G93>0,G12/'Data Sheet'!G93,0) -> 8.4704875 | H13: =IF('Data Sheet'!H93>0,H12/'Data Sheet'!H93,0) -> 9.2354334 | I13: =IF('Data Sheet'!I93>0,I12/'Data Sheet'!I93,0) -> 10.272242 | ... K13: =IF('Data Sheet'!K93>0,K12/'Data Sheet'!K93,0) -> 10.692505 | L13: =IF('Data Sheet'!$B6>0,'Profit & Loss'!L12/'Data Sheet'!$B6,0) -> 11.30817 | M13: =IF('Data Sheet'!$B6>0,'Profit & Loss'!M12/'Data Sheet'!$B6,0) -> 10.934131 | N13: =IF('Data Sheet'!$B6>0,'Profit & Loss'!N12/'Data Sheet'!$B6,0) -> 9.9339953
A14: Price to earning | B14: =IF(B15>0,B15/B13,"") -> 28.347625 | C14: =IF(C15>0,C15/C13,"") -> 32.139715 | D14: =IF(D15>0,D15/D13,"") -> 31.561432 | E14: =IF(E15>0,E15/E13,"") -> 27.02862 | F14: =IF(F15>0,F15/F13,"") -> 28.267615 | G14: =IF(G15>0,G15/G13,"") -> 33.091366 | H14: =IF(H15>0,H15/H13,"") -> 27.665188 | I14: =IF(I15>0,I15/I13,"") -> 28.937209 | ... K14: =IF(K15>0,K15/K13,"") -> 20.434876 | L14: =IF(L13>0,L15/L13,0) -> 18.508741 | M14: =M25 -> 20.417448 | N14: =N25 -> 18.508741
A15: Price | B15: ='Data Sheet'!B90 -> 151.27 | C15: ='Data Sheet'!C90 -> 206.3 | D15: ='Data Sheet'!D90 -> 235.23 | E15: ='Data Sheet'!E90 -> 217.23 | F15: ='Data Sheet'!F90 -> 218.83 | G15: ='Data Sheet'!G90 -> 280.3 | H15: ='Data Sheet'!H90 -> 255.5 | I15: ='Data Sheet'!I90 -> 297.25 | ... K15: ='Data Sheet'!K90 -> 218.5 | L15: ='Data Sheet'!B8 -> 209.3 | M15: =M13*M14 -> 223.24705 | N15: =N13*N14 -> 183.86575
A17: RATIOS:
A18: Dividend Payout | B18: =IF('Data Sheet'!B30>0, 'Data Sheet'!B31/'Data Sheet'!B30, 0) -> 0.5621926 | C18: =IF('Data Sheet'!C30>0, 'Data Sheet'!C31/'Data Sheet'!C30, 0) -> 0.54526838 | D18: =IF('Data Sheet'!D30>0, 'Data Sheet'!D31/'Data Sheet'!D30, 0) -> 0.53669059 | E18: =IF('Data Sheet'!E30>0, 'Data Sheet'!E31/'Data Sheet'!E30, 0) -> 0.51843132 | F18: =IF('Data Sheet'!F30>0, 'Data Sheet'!F31/'Data Sheet'!F30, 0) -> 0.73199814 | G18: =IF('Data Sheet'!G30>0, 'Data Sheet'!G31/'Data Sheet'!G30, 0) -> 0.56077104 | H18: =IF('Data Sheet'!H30>0, 'Data Sheet'!H31/'Data Sheet'!H30, 0) -> 0.5576345 | I18: =IF('Data Sheet'!I30>0, 'Data Sheet'!I31/'Data Sheet'!I30, 0) -> 0.55976138 | ... K18: =IF('Data Sheet'!K30>0, 'Data Sheet'!K31/'Data Sheet'!K30, 0) -> 1.0053772
A19: OPM | B19: =IF(B6>0,B6/B4,0) -> 0.3486178 | C19: =IF(C6>0,C6/C4,0) -> 0.3548758 | D19: =IF(D6>0,D6/D4,0) -> 0.37046793 | E19: =IF(E6>0,E6/E4,0) -> 0.36714751 | F19: =IF(F6>0,F6/F4,0) -> 0.370776 | G19: =IF(G6>0,G6/G4,0) -> 0.36171097 | H19: =IF(H6>0,H6/H4,0) -> 0.38022999 | I19: =IF(I6>0,I6/I4,0) -> 0.38348265 | ... L19: =IF(L6>0,L6/L4,0) -> 0.35075445
G22: TRENDS: | H22: 10 YEARS | I22: 7 YEARS | J22: 5 YEARS | K22: 3 YEARS | L22: RECENT | M22: BEST | N22: WORST
G23: Sales Growth | H23: =IF(B4=0,"",POWER($K4/B4,1/9)-1) -> 0.071235175 | I23: =IF(D4=0,"",POWER($K4/D4,1/7)-1) -> 0.048720437 | J23: =IF(F4=0,"",POWER($K4/F4,1/5)-1) -> 0.046778221 | K23: =IF(H4=0,"",POWER($K4/H4, 1/3)-1) -> 0.0427117 | L23: =IF(ISERROR(MAX(IF(J4=0,"",(K4-J4)/J4),IF(K4=0,"",(L4-K4)/K4))),"",MAX(IF(J4=0,"",(K4-J4)/J4),IF(K4=0,"",(L4-K4)/K4))) -> 0.070821977 | M23: =MAX(K23:L23) -> 0.070821977 | N23: =MIN(H23:L23) -> 0.0427117
G24: OPM | H24: =IF(SUM(B4:$K$4)=0,"",SUMPRODUCT(B19:$K$19,B4:$K$4)/SUM(B4:$K$4)) -> 0.36886909 | I24: =IF(SUM(E4:$K$4)=0,"",SUMPRODUCT(E19:$K$19,E4:$K$4)/SUM(E4:$K$4)) -> 0.37183486 | J24: =IF(SUM(G4:$K$4)=0,"",SUMPRODUCT(G19:$K$19,G4:$K$4)/SUM(G4:$K$4)) -> 0.37279304 | K24: =IF(SUM(I4:$K$4)=0, "", SUMPRODUCT(I19:$K$19,I4:$K$4)/SUM(I4:$K$4)) -> 0.37381917 | L24: =L19 -> 0.35075445 | M24: =MAX(K24:L24) -> 0.37381917 | N24: =MIN(H24:L24) -> 0.35075445
G25: Price to Earning | H25: =IF(ISERROR(AVERAGEIF(B14:$L14,">0")),"",AVERAGEIF(B14:$L14,">0")) -> 26.34285 | I25: =IF(ISERROR(AVERAGEIF(E14:$L14,">0")),"",AVERAGEIF(E14:$L14,">0")) -> 24.715322 | J25: =IF(ISERROR(AVERAGEIF(G14:$L14,">0")),"",AVERAGEIF(G14:$L14,">0")) -> 23.737724 | K25: =IF(ISERROR(AVERAGEIF(I14:$L14,">0")),"",AVERAGEIF(I14:$L14,">0")) -> 20.417448 | L25: =L14 -> 18.508741 | M25: =MAX(K25:L25) -> 20.417448 | N25: =MIN(H25:L25) -> 18.508741

Sheet Quarters
A1: ='Profit & Loss'!A1 -> ITC LTD | E1: =UPDATE | J1: SCREENER.IN
A3: Narration | B3: ='Data Sheet'!B41 -> 43555 | C3: ='Data Sheet'!C41 -> 43646 | D3: ='Data Sheet'!D41 -> 43738 | E3: ='Data Sheet'!E41 -> 43830 | F3: ='Data Sheet'!F41 -> 43921 | G3: ='Data Sheet'!G41 -> 44012 | H3: ='Data Sheet'!H41 -> 44104 | I3: ='Data Sheet'!I41 -> 44196 | ... K3: ='Data Sheet'!K41 -> 44377
A4: Sales | B4: ='Data Sheet'!B42 -> 13212.19 | C4: ='Data Sheet'!C42 -> 12657.9 | D4: ='Data Sheet'!D42 -> 12867.39 | E4: ='Data Sheet'!E42 -> 12902.55 | F4: ='Data Sheet'!F42 -> 11782.16 | G4: ='Data Sheet'!G42 -> 10478.46 | H4: ='Data Sheet'!H42 -> 12076.72 | I4: ='Data Sheet'!I42 -> 13079.72 | ... K4: ='Data Sheet'!K42 -> 13247.25
A5: Expenses | B5: ='Data Sheet'!B43 -> 8379.95 | C5: ='Data Sheet'!C43 -> 7720.15 | D5: ='Data Sheet'!D43 -> 8025.33 | E5: ='Data Sheet'!E43 -> 7925.82 | F5: ='Data Sheet'!F43 -> 7278.54 | G5: ='Data Sheet'!G43 -> 7532.9 | H5: ='Data Sheet'!H43 -> 7675.72 | I5: ='Data Sheet'!I43 -> 8294.7 | ... K5: ='Data Sheet'!K43 -> 8803.51
A6: Operating Profit | B6: ='Data Sheet'!B50 -> 4832.24 | C6: ='Data Sheet'!C50 -> 4937.75 | D6: ='Data Sheet'!D50 -> 4842.06 | E6: ='Data Sheet'!E50 -> 4976.73 | F6: ='Data Sheet'!F50 -> 4503.62 | G6: ='Data Sheet'!G50 -> 2945.56 | H6: ='Data Sheet'!H50 -> 4401 | I6: ='Data Sheet'!I50 -> 4785.02 | ... K6: ='Data Sheet'!K50 -> 4443.74
A7: Other Income | B7: ='Data Sheet'!B44 -> 690.11 | C7: ='Data Sheet'!C44 -> 647.29 | D7: ='Data Sheet'!D44 -> 629.88 | E7: ='Data Sheet'!E44 -> 520.85 | F7: ='Data Sheet'!F44 -> 667.76 | G7: ='Data Sheet'!G44 -> 925.13 | H7: ='Data Sheet'!H44 -> 582.25 | I7: ='Data Sheet'!I44 -> 545.69 | ... K7: ='Data Sheet'!K44 -> 447.04
A8: Depreciation | B8: ='Data Sheet'!B45 -> 370.78 | C8: ='Data Sheet'!C45 -> 378.94 | D8: ='Data Sheet'!D45 -> 415.84 | E8: ='Data Sheet'!E45 -> 436.9 | F8: ='Data Sheet'!F45 -> 413.23 | G8: ='Data Sheet'!G45 -> 418.99 | H8: ='Data Sheet'!H45 -> 404.6 | I8: ='Data Sheet'!I45 -> 413.49 | ... K8: ='Data Sheet'!K45 -> 414.13
A9: Interest | B9: ='Data Sheet'!B46 -> 9.63 | C9: ='Data Sheet'!C46 -> 14.58 | D9: ='Data Sheet'!D46 -> 13.99 | E9: ='Data Sheet'!E46 -> 11.43 | F9: ='Data Sheet'!F46 -> 14.68 | G9: ='Data Sheet'!G46 -> 15.82 | H9: ='Data Sheet'!H46 -> 13.27 | I9: ='Data Sheet'!I46 -> 12.61 | ... K9: ='Data Sheet'!K46 -> 9.34
A10: Profit before tax | B10: ='Data Sheet'!B47 -> 5141.94 | C10: ='Data Sheet'!C47 -> 5191.52 | D10: ='Data Sheet'!D47 -> 5042.11 | E10: ='Data Sheet'!E47 -> 5049.25 | F10: ='Data Sheet'!F47 -> 4743.47 | G10: ='Data Sheet'!G47 -> 3435.88 | H10: ='Data Sheet'!H47 -> 4565.38 | I10: ='Data Sheet'!I47 -> 4904.61 | ... K10: ='Data Sheet'!K47 -> 4467.31
A11: Tax | B11: ='Data Sheet'!B48 -> 1549.14 | C11: ='Data Sheet'!C48 -> 1755.01 | D11: ='Data Sheet'!D48 -> 868.39 | E11: ='Data Sheet'!E48 -> 1001.38 | F11: ='Data Sheet'!F48 -> 817.01 | G11: ='Data Sheet'!G48 -> 868.81 | H11: ='Data Sheet'!H48 -> 1146.69 | I11: ='Data Sheet'!I48 -> 1317.41 | ... K11: ='Data Sheet'!K48 -> 1123.87
A12: Net profit | B12: ='Data Sheet'!B49 -> 3535.11 | C12: ='Data Sheet'!C49 -> 3355.01 | D12: ='Data Sheet'!D49 -> 4119.16 | E12: ='Data Sheet'!E49 -> 3975.54 | F12: ='Data Sheet'!F49 -> 3856.52 | G12: ='Data Sheet'!G49 -> 2511 | H12: ='Data Sheet'!H49 -> 3368.17 | I12: ='Data Sheet'!I49 -> 3526.55 | ... K12: ='Data Sheet'!K49 -> 3276.48
A14: OPM | B14: =IF(B4>0,B6/B4,"") -> 0.36574103 | C14: =IF(C4>0,C6/C4,"") -> 0.39009235 | D14: =IF(D4>0,D6/D4,"") -> 0.37630475 | E14: =IF(E4>0,E6/E4,"") -> 0.38571678 | F14: =IF(F4>0,F6/F4,"") -> 0.38224061 | G14: =IF(G4>0,G6/G4,"") -> 0.28110619 | H14: =IF(H4>0,H6/H4,"") -> 0.36442014 | I14: =IF(I4>0,I6/I4,"") -> 0.36583505 | ... K14: =IF(K4>0,K6/K4,"") -> 0.33544622

Sheet Balance Sheet
A1: ='Profit & Loss'!A1 -> ITC LTD | E1: =UPDATE | J1: SCREENER.IN
A3: Narration | B3: ='Data Sheet'!B56 -> 40999 | C3: ='Data Sheet'!C56 -> 41364 | D3: ='Data Sheet'!D56 -> 41729 | E3: ='Data Sheet'!E56 -> 42094 | F3: ='Data Sheet'!F56 -> 42460 | G3: ='Data Sheet'!G56 -> 42825 | H3: ='Data Sheet'!H56 -> 43190 | I3: ='Data Sheet'!I56 -> 43555 | ... K3: ='Data Sheet'!K56 -> 44286
A4: Equity Share Capital | B4: ='Data Sheet'!B57 -> 781.84 | C4: ='Data Sheet'!C57 -> 790.18 | D4: ='Data Sheet'!D57 -> 795.32 | E4: ='Data Sheet'!E57 -> 801.55 | F4: ='Data Sheet'!F57 -> 804.72 | G4: ='Data Sheet'!G57 -> 1214.74 | H4: ='Data Sheet'!H57 -> 1220.43 | I4: ='Data Sheet'!I57 -> 1225.86 | ... K4: ='Data Sheet'!K57 -> 1230.88
A5: Reserves | B5: ='Data Sheet'!B58 -> 18676.74 | C5: ='Data Sheet'!C58 -> 22367.72 | D5: ='Data Sheet'!D58 -> 26441.64 | E5: ='Data Sheet'!E58 -> 30933.94 | F5: ='Data Sheet'!F58 -> 41874.8 | G5: ='Data Sheet'!G58 -> 45198.19 | H5: ='Data Sheet'!H58 -> 51289.68 | I5: ='Data Sheet'!I58 -> 57915.01 | ... K5: ='Data Sheet'!K58 -> 59116.46
A6: Borrowings | B6: ='Data Sheet'!B59 -> 117.6 | C6: ='Data Sheet'!C59 -> 102.38 | D6: ='Data Sheet'!D59 -> 242.41 | E6: ='Data Sheet'!E59 -> 268.8 | F6: ='Data Sheet'!F59 -> 83.78 | G6: ='Data Sheet'!G59 -> 45.72 | H6: ='Data Sheet'!H59 -> 35.92 | I6: ='Data Sheet'!I59 -> 13.44 | ... K6: ='Data Sheet'!K59 -> 270.83
A7: Other Liabilities | B7: ='Data Sheet'!B60 -> 10509.13 | C7: ='Data Sheet'!C60 -> 12068.99 | D7: ='Data Sheet'!D60 -> 13369.04 | E7: ='Data Sheet'!E60 -> 13947.93 | F7: ='Data Sheet'!F60 -> 8888.04 | G7: ='Data Sheet'!G60 -> 9439.67 | H7: ='Data Sheet'!H60 -> 11694.85 | I7: ='Data Sheet'!I60 -> 12584.73 | ... K7: ='Data Sheet'!K60 -> 13142.59
A8: Total | B8: ='Data Sheet'!B61 -> 30085.31 | C8: ='Data Sheet'!C61 -> 35329.27 | D8: ='Data Sheet'!D61 -> 40848.41 | E8: ='Data Sheet'!E61 -> 45952.22 | F8: ='Data Sheet'!F61 -> 51651.34 | G8: ='Data Sheet'!G61 -> 55898.32 | H8: ='Data Sheet'!H61 -> 64240.88 | I8: ='Data Sheet'!I61 -> 71739.04 | ... K8: ='Data Sheet'!K61 -> 73760.76
A10: Net Block | B10: ='Data Sheet'!B62 -> 10007.42 | C10: ='Data Sheet'!C62 -> 12139.83 | D10: ='Data Sheet'!D62 -> 12921.3 | E10: ='Data Sheet'!E62 -> 15303.28 | F10: ='Data Sheet'!F62 -> 15106.63 | G10: ='Data Sheet'!G62 -> 15893.48 | H10: ='Data Sheet'!H62 -> 16523.96 | I10: ='Data Sheet'!I62 -> 19374.19 | ... K10: ='Data Sheet'!K62 -> 23298.48
A11: Capital Work in Progress | B11: ='Data Sheet'!B63 -> 2396.46 | C11: ='Data Sheet'!C63 -> 2062.03 | D11: ='Data Sheet'!D63 -> 3117.37 | E11: ='Data Sheet'!E63 -> 2700.2 | F11: ='Data Sheet'!F63 -> 2559.72 | G11: ='Data Sheet'!G63 -> 3729.89 | H11: ='Data Sheet'!H63 -> 5508.33 | I11: ='Data Sheet'!I63 -> 4136.42 | ... K11: ='Data Sheet'!K63 -> 4011.29
A12: Investments | B12: ='Data Sheet'!B64 -> 5206.83 | C12: ='Data Sheet'!C64 -> 5981.28 | D12: ='Data Sheet'!D64 -> 7284.02 | E12: ='Data Sheet'!E64 -> 6942.77 | F12: ='Data Sheet'!F64 -> 11747.59 | G12: ='Data Sheet'!G64 -> 17581.38 | H12: ='Data Sheet'!H64 -> 22052.86 | I12: ='Data Sheet'!I64 -> 25043.49 | ... K12: ='Data Sheet'!K64 -> 24870.87
A13: Other Assets | B13: ='Data Sheet'!B65 -> 12474.6 | C13: ='Data Sheet'!C65 -> 15146.13 | D13: ='Data Sheet'!D65 -> 17525.72 | E13: ='Data Sheet'!E65 -> 21005.97 | F13: ='Data Sheet'!F65 -> 22237.4 | G13: ='Data Sheet'!G65 -> 18693.57 | H13: ='Data Sheet'!H65 -> 20155.73 | I13: ='Data Sheet'!I65 -> 23184.94 | ... K13: ='Data Sheet'!K65 -> 21580.12
A14: Total | B14: ='Data Sheet'!B66 -> 30085.31 | C14: ='Data Sheet'!C66 -> 35329.27 | D14: ='Data Sheet'!D66 -> 40848.41 | E14: ='Data Sheet'!E66 -> 45952.22 | F14: ='Data Sheet'!F66 -> 51651.34 | G14: ='Data Sheet'!G66 -> 55898.32 | H14: ='Data Sheet'!H66 -> 64240.88 | I14: ='Data Sheet'!I66 -> 71739.04 | ... K14: ='Data Sheet'!K66 -> 73760.76
A16: Working Capital | B16: =B13-B7 -> 1965.47 | C16: =C13-C7 -> 3077.14 | D16: =D13-D7 -> 4156.68 | E16: =E13-E7 -> 7058.04 | F16: =F13-F7 -> 13349.36 | G16: =G13-G7 -> 9253.9 | H16: =H13-H7 -> 8460.88 | I16: =I13-I7 -> 10600.21 | ... K16: =K13-K7 -> 8437.53
A17: Debtors | B17: ='Data Sheet'!B67 -> 1200.2 | C17: ='Data Sheet'!C67 -> 1395.76 | D17: ='Data Sheet'!D67 -> 2439.21 | E17: ='Data Sheet'!E67 -> 1982.07 | F17: ='Data Sheet'!F67 -> 1917.18 | G17: ='Data Sheet'!G67 -> 2474.29 | H17: ='Data Sheet'!H67 -> 2682.29 | I17: ='Data Sheet'!I67 -> 4035.28 | ... K17: ='Data Sheet'!K67 -> 2501.7
A18: Inventory | B18: ='Data Sheet'!B68 -> 6426.87 | C18: ='Data Sheet'!C68 -> 7522.09 | D18: ='Data Sheet'!D68 -> 8255.24 | E18: ='Data Sheet'!E68 -> 8586.87 | F18: ='Data Sheet'!F68 -> 9062.1 | G18: ='Data Sheet'!G68 -> 8116.1 | H18: ='Data Sheet'!H68 -> 7495.09 | I18: ='Data Sheet'!I68 -> 7859.56 | ... K18: ='Data Sheet'!K68 -> 10397.16
A20: Debtor Days | B20: =IF('Profit & Loss'!B4>0,'Balance Sheet'!B17/('Profit & Loss'!B4/365),0) -> 16.521063 | C20: =IF('Profit & Loss'!C4>0,'Balance Sheet'!C17/('Profit & Loss'!C4/365),0) -> 16.112565 | D20: =IF('Profit & Loss'!D4>0,'Balance Sheet'!D17/('Profit & Loss'!D4/365),0) -> 25.2167 | E20: =IF('Profit & Loss'!E4>0,'Balance Sheet'!E17/('Profit & Loss'!E4/365),0) -> 18.637524 | F20: =IF('Profit & Loss'!F4>0,'Balance Sheet'!F17/('Profit & Loss'!F4/365),0) -> 17.854892 | G20: =IF('Profit & Loss'!G4>0,'Balance Sheet'!G17/('Profit & Loss'!G4/365),0) -> 21.116823 | H20: =IF('Profit & Loss'!H4>0,'Balance Sheet'!H17/('Profit & Loss'!H4/365),0) -> 22.53302 | I20: =IF('Profit & Loss'!I4>0,'Balance Sheet'!I17/('Profit & Loss'!I4/365),0) -> 30.469383 | ... K20: =IF('Profit & Loss'!K4>0,'Balance Sheet'!K17/('Profit & Loss'!K4/365),0) -> 18.537714
A21: Inventory Turnover | B21: =IF('Balance Sheet'!B18>0,'Profit & Loss'!B4/'Balance Sheet'!B18,0) -> 4.1258077 | C21: =IF('Balance Sheet'!C18>0,'Profit & Loss'!C4/'Balance Sheet'!C18,0) -> 4.2033969 | D21: =IF('Balance Sheet'!D18>0,'Profit & Loss'!D4/'Balance Sheet'!D18,0) -> 4.2768508 | E21: =IF('Balance Sheet'!E18>0,'Profit & Loss'!E4/'Balance Sheet'!E18,0) -> 4.5205238 | F21: =IF('Balance Sheet'!F18>0,'Profit & Loss'!F4/'Balance Sheet'!F18,0) -> 4.3248364 | G21: =IF('Balance Sheet'!G18>0,'Profit & Loss'!G4/'Balance Sheet'!G18,0) -> 5.2694767 | H21: =IF('Balance Sheet'!H18>0,'Profit & Loss'!H4/'Balance Sheet'!H18,0) -> 5.7969871 | I21: =IF('Balance Sheet'!I18>0,'Profit & Loss'!I4/'Balance Sheet'!I18,0) -> 6.1504181 | ... K21: =IF('Balance Sheet'!K18>0,'Profit & Loss'!K4/'Balance Sheet'!K18,0) -> 4.737587
A23: Return on Equity | B23: =IF(SUM('Balance Sheet'!B4:B5)>0,'Profit & Loss'!B12/SUM('Balance Sheet'!B4:B5),"") -> 0.3216134 | C23: =IF(SUM('Balance Sheet'!C4:C5)>0,'Profit & Loss'!C12/SUM('Balance Sheet'!C4:C5),"") -> 0.32853022 | D23: =IF(SUM('Balance Sheet'!D4:D5)>0,'Profit & Loss'!D12/SUM('Balance Sheet'!D4:D5),"") -> 0.32644539 | E23: =IF(SUM('Balance Sheet'!E4:E5)>0,'Profit & Loss'!E12/SUM('Balance Sheet'!E4:E5),"") -> 0.30449097 | F23: =IF(SUM('Balance Sheet'!F4:F5)>0,'Profit & Loss'!F12/SUM('Balance Sheet'!F4:F5),"") -> 0.21894459 | G23: =IF(SUM('Balance Sheet'!G4:G5)>0,'Profit & Loss'!G12/SUM('Balance Sheet'!G4:G5),"") -> 0.22169339 | H23: =IF(SUM('Balance Sheet'!H4:H5)>0,'Profit & Loss'!H12/SUM('Balance Sheet'!H4:H5),"") -> 0.21464819 | I23: =IF(SUM('Balance Sheet'!I4:I5)>0,'Profit & Loss'!I12/SUM('Balance Sheet'!I4:I5),"") -> 0.21292095 | ... K23: =IF(SUM('Balance Sheet'!K4:K5)>0,'Profit & Loss'!K12/SUM('Balance Sheet'!K4:K5),"") -> 0.21809064
A24: Return on Capital Emp | C24: =IF((B4+B5+B6+C4+C5+C6)>0,('Profit & Loss'!C10+'Profit & Loss'!C9)*2/(B4+B5+B6+C4+C5+C6),"") -> 0.5235624 | D24: =IF((C4+C5+C6+D4+D5+D6)>0,('Profit & Loss'!D10+'Profit & Loss'!D9)*2/(C4+C5+C6+D4+D5+D6),"") -> 0.51560151 | E24: =IF((D4+D5+D6+E4+E5+E6)>0,('Profit & Loss'!E10+'Profit & Loss'!E9)*2/(D4+D5+D6+E4+E5+E6),"") -> 0.48594891 | F24: =IF((E4+E5+E6+F4+F5+F6)>0,('Profit & Loss'!F10+'Profit & Loss'!F9)*2/(E4+E5+E6+F4+F5+F6),"") -> 0.3995635 | G24: =IF((F4+F5+F6+G4+G5+G6)>0,('Profit & Loss'!G10+'Profit & Loss'!G9)*2/(F4+F5+F6+G4+G5+G6),"") -> 0.36034518 | H24: =IF((G4+G5+G6+H4+H5+H6)>0,('Profit & Loss'!H10+'Profit & Loss'!H9)*2/(G4+G5+G6+H4+H5+H6),"") -> 0.35400589 | I24: =IF((H4+H5+H6+I4+I5+I6)>0,('Profit & Loss'!I10+'Profit & Loss'!I9)*2/(H4+H5+H6+I4+I5+I6),"") -> 0.34415688 | J24: =IF((I4+I5+I6+J4+J5+J6)>0,('Profit & Loss'!J10+'Profit & Loss'!J9)*2/(I4+I5+I6+J4+J5+J6),"") -> 0.32261652 | K24: =IF((J4+J5+J6+K4+K5+K6)>0,('Profit & Loss'!K10+'Profit & Loss'!K9)*2/(J4+J5+J6+K4+K5+K6),"") -> 0.28527066

Sheet Cash Flow
A1: ='Balance Sheet'!A1 -> ITC LTD | E1: =UPDATE | J1: SCREENER.IN
A3: Narration | B3: ='Data Sheet'!B81 -> 40999 | C3: ='Data Sheet'!C81 -> 41364 | D3: ='Data Sheet'!D81 -> 41729 | E3: ='Data Sheet'!E81 -> 42094 | F3: ='Data Sheet'!F81 -> 42460 | G3: ='Data Sheet'!G81 -> 42825 | H3: ='Data Sheet'!H81 -> 43190 | I3: ='Data Sheet'!I81 -> 43555 | ... K3: ='Data Sheet'!K81 -> 44286
A4: Cash from Operating Activity | B4: ='Data Sheet'!B82 -> 6255.66 | C4: ='Data Sheet'!C82 -> 7101.83 | D4: ='Data Sheet'!D82 -> 7343.58 | E4: ='Data Sheet'!E82 -> 9843.2 | F4: ='Data Sheet'!F82 -> 9799.04 | G4: ='Data Sheet'!G82 -> 10627.31 | H4: ='Data Sheet'!H82 -> 13169.4 | I4: ='Data Sheet'!I82 -> 12583.41 | ... K4: ='Data Sheet'!K82 -> 12527.09
A5: Cash from Investing Activity | B5: ='Data Sheet'!B83 -> -2693.8 | C5: ='Data Sheet'!C83 -> -3881.35 | D5: ='Data Sheet'!D83 -> -3254.08 | E5: ='Data Sheet'!E83 -> -5275.43 | F5: ='Data Sheet'!F83 -> -3920.73 | G5: ='Data Sheet'!G83 -> -3250.93 | H5: ='Data Sheet'!H83 -> -7113.89 | I5: ='Data Sheet'!I83 -> -5545.68 | ... K5: ='Data Sheet'!K83 -> 5739.86
A6: Cash from Financing Activity | B6: ='Data Sheet'!B84 -> -3304.65 | C6: ='Data Sheet'!C84 -> -3310.01 | D6: ='Data Sheet'!D84 -> -4121.54 | E6: ='Data Sheet'!E84 -> -4661.03 | F6: ='Data Sheet'!F84 -> -5612.52 | G6: ='Data Sheet'!G84 -> -7301.03 | H6: ='Data Sheet'!H84 -> -6221.13 | I6: ='Data Sheet'!I84 -> -6868.64 | ... K6: ='Data Sheet'!K84 -> -18633.83
A7: Net Cash Flow | B7: ='Data Sheet'!B85 -> 257.21 | C7: ='Data Sheet'!C85 -> -89.53 | D7: ='Data Sheet'!D85 -> -32.04 | E7: ='Data Sheet'!E85 -> -93.26 | F7: ='Data Sheet'!F85 -> 265.79 | G7: ='Data Sheet'!G85 -> 75.35 | H7: ='Data Sheet'!H85 -> -165.62 | I7: ='Data Sheet'!I85 -> 169.09 | ... K7: ='Data Sheet'!K85 -> -366.88
A8: CAPEX
A9: FCF | B9: =B4-B8 -> 6255.66 | C9: =C4-C8 -> 7101.83 | D9: =D4-D8 -> 7343.58 | E9: =E4-E8 -> 9843.2 | F9: =F4-F8 -> 9799.04 | G9: =G4-G8 -> 10627.31 | H9: =H4-H8 -> 13169.4 | I9: =I4-I8 -> 12583.41 | ... K9: =K4-K8 -> 12527.09
K10: =AVERAGE(G9:K9) -> 12719.374
A11: GROWTH RATE | C11: =(C9-B9)/B9 -> 0.1352647 | D11: =(D9-C9)/C9 -> 0.034040522 | E11: =(E9-D9)/D9 -> 0.34038167 | F11: =(F9-E9)/E9 -> -0.0044863459 | G11: =(G9-F9)/F9 -> 0.084525627 | H11: =(H9-G9)/G9 -> 0.23920352 | I11: =(I9-H9)/H9 -> -0.044496332 | J11: =(J9-I9)/I9 -> 0.16738309 | K11: =(K9-J9)/J9 -> -0.14721716
K12: =AVERAGE(C11:K11) -> 0.089399921

Sheet Data Sheet
A1: COMPANY NAME | B1: ITC LTD | E1: =IF(B2<>B3, "A NEW VERSION OF THE WORKSHEET IS AVAILABLE", "")
A2: LATEST VERSION | B2: 2.1 | E2: PLEASE DO NOT MAKE ANY CHANGES TO THIS SHEET
A3: CURRENT VERSION | B3: 2.1
A5: META
A6: Number of shares | B6: =IF(B9>0, B9/B8, 0) -> 1231.5582
A7: Face Value | B7: 1
A8: Current Price | B8: 209.3
A9: Market Capitalization | B9: 257765.13
A15: PROFIT & LOSS
A16: Report Date | B16: 40999 | C16: 41364 | D16: 41729 | E16: 42094 | F16: 42460 | G16: 42825 | H16: 43190 | I16: 43555 | J16: 43921 | K16: 44286
A17: Sales | B17: 26516.03 | C17: 31618.33 | D17: 35306.43 | E17: 38817.15 | F17: 39192.1 | G17: 42767.6 | H17: 43448.94 | I17: 48339.58 | J17: 49387.7 | K17: 49257.45
A18: Raw Material Cost | B18: 9729.93 | C18: 12375.05 | D18: 13353.03 | E18: 15007.9 | F18: 13763.88 | G18: 15456.59 | H18: 14827.72 | I18: 17623.52 | J18: 18048.6 | K18: 20776.71
A19: Change in Inventory | B19: 85.74 | C19: 256.84 | D19: 112.74 | E19: 235.72 | F19: 195.38 | G19: -592.57 | H19: -1027.76 | I19: 203.19 | J19: 703.13 | K19: 645.27
A20: Power and Fuel | B20: 476.74 | C20: 579.98 | D20: 644.96 | E20: 610.67 | F20: 571.88 | G20: 584.33 | H20: 653.5 | I20: 746.73 | J20: 780.85 | K20: 699.56
A21: Other Mfr. Exp | B21: 1106.46 | C21: 1213.67 | D21: 1395.57 | E21: 1533.25 | F21: 1581.59 | G21: 1683.9 | H21: 1697.62 | I21: 1871.01 | J21: 1908.29 | K21: 1587.18
A22: Employee Cost | B22: 1935.11 | C22: 2145.63 | D22: 2504.24 | E22: 2772.28 | F22: 3440.97 | G22: 3631.73 | H22: 3760.9 | I22: 4177.88 | J22: 4295.79 | K22: 4463.33
A23: Selling and admin | B23: 3177.05 | C23: 3543.86 | D23: 3361.2 | E23: 3876.19 | F23: 4261.78 | G23: 4179.74 | H23: 3954.87 | I23: 4546.39 | J23: 4488.63 | K23: 4236.77
A24: Other Expenses | B24: 932.52 | C24: 796.4 | D24: 1080.27 | E24: 1000.96 | F24: 1235.89 | G24: 1169.23 | H24: 1005.98 | I24: 1039.85 | J24: 1225.13 | K24: 1074.39
A25: Other Income | B25: 771.71 | C25: 852.31 | D25: 965.74 | E25: 1229.35 | F25: 1483.11 | G25: 1758.63 | H25: 2239.81 | I25: 2080.44 | J25: 2417.32 | K25: 2576.95
A26: Depreciation | B26: 745.48 | C26: 859.11 | D26: 964.92 | E26: 1027.96 | F26: 1077.4 | G26: 1152.79 | H26: 1236.28 | I26: 1396.61 | J26: 1644.91 | K26: 1645.59
A27: Interest | B27: 102.04 | C27: 108.13 | D27: 29.17 | E27: 90.96 | F27: 78.13 | G27: 49.03 | H27: 115.01 | I27: 71.4 | J27: 81.38 | K27: 57.97
... A31: Dividend Amount | B31: 3518.28 | C31: 4148.44 | D31: 4771.92 | E31: 5009.69 | F31: 6840.12 | G31: 5770.02 | H31: 6285.21 | I31: 7048.7 | J31: 12476.58 | K31: 13231.96
A40: Quarters
A41: Report Date | B41: 43555 | C41: 43646 | D41: 43738 | E41: 43830 | F41: 43921 | G41: 44012 | H41: 44104 | I41: 44196 | J41: 44286 | K41: 44377
A42: Sales | B42: 13212.19 | C42: 12657.9 | D42: 12867.39 | E42: 12902.55 | F42: 11782.16 | G42: 10478.46 | H42: 12076.72 | I42: 13079.72 | J42: 14342.27 | K42: 13247.25
A43: Expenses | B43: 8379.95 | C43: 7720.15 | D43: 8025.33 | E43: 7925.82 | F43: 7278.54 | G43: 7532.9 | H43: 7675.72 | I43: 8294.7 | J43: 9471.15 | K43: 8803.51
A44: Other Income | B44: 690.11 | C44: 647.29 | D44: 629.88 | E44: 520.85 | F44: 667.76 | G44: 925.13 | H44: 582.25 | I44: 545.69 | J44: 579.49 | K44: 447.04
A45: Depreciation | B45: 370.78 | C45: 378.94 | D45: 415.84 | E45: 436.9 | F45: 413.23 | G45: 418.99 | H45: 404.6 | I45: 413.49 | J45: 408.51 | K45: 414.13
A46: Interest | B46: 9.63 | C46: 14.58 | D46: 13.99 | E46: 11.43 | F46: 14.68 | G46: 15.82 | H46: 13.27 | I46: 12.61 | J46: 2.88 | K46: 9.34
A47: Profit before tax | B47: 5141.94 | C47: 5191.52 | D47: 5042.11 | E47: 5049.25 | F47: 4743.47 | G47: 3435.88 | H47: 4565.38 | I47: 4904.61 | J47: 5039.22 | K47: 4467.31
A48: Tax | B48: 1549.14 | C48: 1755.01 | D48: 868.39 | E48: 1001.38 | F48: 817.01 | G48: 868.81 | H48: 1146.69 | I48: 1317.41 | J48: 1222.38 | K48: 1123.87
A49: Net profit | B49: 3535.11 | C49: 3355.01 | D49: 4119.16 | E49: 3975.54 | F49: 3856.52 | G49: 2511 | H49: 3368.17 | I49: 3526.55 | J49: 3755.47 | K49: 3276.48
A50: Operating Profit | B50: 4832.24 | C50: 4937.75 | D50: 4842.06 | E50: 4976.73 | F50: 4503.62 | G50: 2945.56 | H50: 4401 | I50: 4785.02 | J50: 4871.12 | K50: 4443.74
A55: BALANCE SHEET
A56: Report Date | B56: 40999 | C56: 41364 | D56: 41729 | E56: 42094 | F56: 42460 | G56: 42825 | H56: 43190 | I56: 43555 | J56: 43921 | K56: 44286
A57: Equity Share Capital | B57: 781.84 | C57: 790.18 | D57: 795.32 | E57: 801.55 | F57: 804.72 | G57: 1214.74 | H57: 1220.43 | I57: 1225.86 | J57: 1229.22 | K57: 1230.88
A58: Reserves | B58: 18676.74 | C58: 22367.72 | D58: 26441.64 | E58: 30933.94 | F58: 41874.8 | G58: 45198.19 | H58: 51289.68 | I58: 57915.01 | J58: 64044.04 | K58: 59116.46
A59: Borrowings | B59: 117.6 | C59: 102.38 | D59: 242.41 | E59: 268.8 | F59: 83.78 | G59: 45.72 | H59: 35.92 | I59: 13.44 | J59: 277.45 | K59: 270.83
A60: Other Liabilities | B60: 10509.13 | C60: 12068.99 | D60: 13369.04 | E60: 13947.93 | F60: 8888.04 | G60: 9439.67 | H60: 11694.85 | I60: 12584.73 | J60: 11760.04 | K60: 13142.59
A61: Total | B61: 30085.31 | C61: 35329.27 | D61: 40848.41 | E61: 45952.22 | F61: 51651.34 | G61: 55898.32 | H61: 64240.88 | I61: 71739.04 | J61: 77310.75 | K61: 73760.76
...

Sheet DCF
B4: AVERAGE FCF | D4: ='Cash Flow'!K10 -> 12719.374
B5: OPTIMISTIC CASE | H5: BALANCED CASE | N5: CONSERVATIVE CASE
B6: YEARS | C6: 1 To 5 | D6: 6 To 10 | H6: YEARS | I6: 1 To 5 | J6: 6 To 10 | N6: YEARS | O6: 1 To 5 | P6: 6 To 10
B7: Growth Rate | C7: 0 | D7: 0 | H7: Growth Rate | I7: 0 | J7: 0 | N7: Growth Rate | O7: 0 | P7: 0
B8: Discount Rate | C8: 0
B9: Terminal Growth Rate | C9: 0 | E9: To Support your channel, open the Demat Account by using the links below & Also avail 15% discount on Tijori
B10: Shares Outstanding | C10: 0 | E10: Tijori Finance Discount Link | H10: Angel Broking | I10: www.tinyurl.com/y3r42a2x | N10: Fyers | O10: www.tinyurl.com/wdunurz5
B11: Net Debt level | C11: ='Data Sheet'!K59-'Data Sheet'!K69 -> -4388.19 | E11: www.tinyurl.com/vk645vp3 | H11: Upstox | I11: www.tinyurl.com/y8sbw9w8 | N11: IIFL Securities | O11: www.tinyurl.com/6uchvnvh
H12: Zerodha | I12: www.zerodha.com/open-account?c=ZMPVNW
B15: YEAR | C15: FCF | D15: GROWTH | E15: PRESENT VALUE | H15: YEAR | I15: FCF | J15: GROWTH | K15: PRESENT VALUE | N15: YEAR | O15: FCF | P15: GROWTH | Q15: PRESENT VALUE
B16: 1 | C16: =D4*(1+D16) -> 12719.374 | D16: =$C$7 -> 0 | E16: =PV($C$8,B16,0,-C16,0) -> 12719.374 | H16: 1 | I16: =D4*(1+J16) -> 12719.374 | J16: =I7 -> 0 | K16: =PV($C$8,H16,0,-I16,0) -> 12719.374 | N16: 1 | O16: =D4*(1+P16) -> 12719.374 | P16: =O7 -> 0 | Q16: =PV($C$8,N16,0,-O16,0) -> 12719.374
B17: 2 | C17: =C16*(1+D17) -> 12719.374 | D17: =$C$7 -> 0 | E17: =PV($C$8,B17,0,-C17,0) -> 12719.374 | H17: 2 | I17: =I16*(1+J17) -> 12719.374 | J17: =J16 -> 0 | K17: =PV($C$8,H17,0,-I17,0) -> 12719.374 | N17: 2 | O17: =O16*(1+P17) -> 12719.374 | P17: =P16 -> 0 | Q17: =PV($C$8,N17,0,-O17,0) -> 12719.374
B18: 3 | C18: =C17*(1+D18) -> 12719.374 | D18: =$C$7 -> 0 | E18: =PV($C$8,B18,0,-C18,0) -> 12719.374 | H18: 3 | I18: =I17*(1+J18) -> 12719.374 | J18: =J17 -> 0 | K18: =PV($C$8,H18,0,-I18,0) -> 12719.374 | N18: 3 | O18: =O17*(1+P18) -> 12719.374 | P18: =P17 -> 0 | Q18: =PV($C$8,N18,0,-O18,0) -> 12719.374
B19: 4 | C19: =C18*(1+D19) -> 12719.374 | D19: =$C$7 -> 0 | E19: =PV($C$8,B19,0,-C19,0) -> 12719.374 | H19: 4 | I19: =I18*(1+J19) -> 12719.374 | J19: =J18 -> 0 | K19: =PV($C$8,H19,0,-I19,0) -> 12719.374 | N19: 4 | O19: =O18*(1+P19) -> 12719.374 | P19: =P18 -> 0 | Q19: =PV($C$8,N19,0,-O19,0) -> 12719.374
B20: 5 | C20: =C19*(1+D20) -> 12719.374 | D20: =$C$7 -> 0 | E20: =PV($C$8,B20,0,-C20,0) -> 12719.374 | H20: 5 | I20: =I19*(1+J20) -> 12719.374 | J20: =J19 -> 0 | K20: =PV($C$8,H20,0,-I20,0) -> 12719.374 | N20: 5 | O20: =O19*(1+P20) -> 12719.374 | P20: =P19 -> 0 | Q20: =PV($C$8,N20,0,-O20,0) -> 12719.374
B21: 6 | C21: =C20*(1+D21) -> 12719.374 | D21: =$D$7 -> 0 | E21: =PV($C$8,B21,0,-C21,0) -> 12719.374 | H21: 6 | I21: =I20*(1+J21) -> 12719.374 | J21: =J7 -> 0 | K21: =PV($C$8,H21,0,-I21,0) -> 12719.374 | N21: 6 | O21: =O20*(1+P21) -> 12719.374 | P21: =P7 -> 0 | Q21: =PV($C$8,N21,0,-O21,0) -> 12719.374
B22: 7 | C22: =C21*(1+D22) -> 12719.374 | D22: =$D$7 -> 0 | E22: =PV($C$8,B22,0,-C22,0) -> 12719.374 | H22: 7 | I22: =I21*(1+J22) -> 12719.374 | J22: =J21 -> 0 | K22: =PV($C$8,H22,0,-I22,0) -> 12719.374 | N22: 7 | O22: =O21*(1+P22) -> 12719.374 | P22: =P21 -> 0 | Q22: =PV($C$8,N22,0,-O22,0) -> 12719.374
B23: 8 | C23: =C22*(1+D23) -> 12719.374 | D23: =$D$7 -> 0 | E23: =PV($C$8,B23,0,-C23,0) -> 12719.374 | H23: 8 | I23: =I22*(1+J23) -> 12719.374 | J23: =J22 -> 0 | K23: =PV($C$8,H23,0,-I23,0) -> 12719.374 | N23: 8 | O23: =O22*(1+P23) -> 12719.374 | P23: =P22 -> 0 | Q23: =PV($C$8,N23,0,-O23,0) -> 12719.374
B24: 9 | C24: =C23*(1+D24) -> 12719.374 | D24: =$D$7 -> 0 | E24: =PV($C$8,B24,0,-C24,0) -> 12719.374 | H24: 9 | I24: =I23*(1+J24) -> 12719.374 | J24: =J23 -> 0 | K24: =PV($C$8,H24,0,-I24,0) -> 12719.374 | N24: 9 | O24: =O23*(1+P24) -> 12719.374 | P24: =P23 -> 0 | Q24: =PV($C$8,N24,0,-O24,0) -> 12719.374
B25: 10 | C25: =C24*(1+D25) -> 12719.374 | D25: =$D$7 -> 0 | E25: =PV($C$8,B25,0,-C25,0) -> 12719.374 | H25: 10 | I25: =I24*(1+J25) -> 12719.374 | J25: =J24 -> 0 | K25: =PV($C$8,H25,0,-I25,0) -> 12719.374 | N25: 10 | O25: =O24*(1+P25) -> 12719.374 | P25: =P24 -> 0 | Q25: =PV($C$8,N25,0,-O25,0) -> 12719.374
C27: FINAL CALCULATION | I27: FINAL CALCULATION | O27: FINAL CALCULATION
C28: Terminal Year Cash Flow | D28: =C25*(1+C9) -> 12719.374 | I28: Terminal Year Cash Flow | J28: =I25*(1+C9) -> 12719.374 | O28: Terminal Year Cash Flow | P28: =O25*(1+C9) -> 12719.374
C29: PV of Year 1-10 Cash Flows | D29: =SUM(E16:E25) -> 127193.74 | I29: PV of Year 1-10 Cash Flows | J29: =SUM(K16:K25) -> 127193.74 | O29: PV of Year 1-10 Cash Flows | P29: =SUM(Q16:Q25) -> 127193.74
C30: Terminal Value | D30: =((D28/($C$8-$C$9))/(1+$C$8)^B25) -> #DIV/0! | I30: Terminal Value | J30: =((J28)/($C$8-$C$9))/(1+$C$8)^H25 -> #DIV/0! | O30: Terminal Value | P30: =((P28)/($C$8-$C$9))/(1+$C$8)^N25 -> #DIV/0!
C31: Total PV of Cash flows: | D31: =D29+D30 -> #DIV/0! | I31: Total PV of Cash flows: | J31: =J29+J30 -> #DIV/0! | O31: Total PV of Cash flows: | P31: =P29+P30 -> #DIV/0!
C32: DCF Price | D32: =(D31-$C$11)/$C$10 -> #DIV/0! | I32: DCF Price | J32: =(J31-$C$11)/$C$10 -> #DIV/0! | O32: DCF Price | P32: =(P31-$C$11)/$C$10 -> #DIV/0!
